<?xml version="1.0" ?>
<!-- =================================================================================== -->
<!-- |    This document was autogenerated by xacro from lidar_x.xacro                  | -->
<!-- |    EDITING THIS FILE BY HAND IS NOT RECOMMENDED                                 | -->
<!-- =================================================================================== -->
<robot name="lazDar">
  <gazebo reference="laz_base">
    <material>Gazebo/Red</material>
    <mu1>0.2</mu1>
    <mu2>0.2</mu2>
  </gazebo>
  <link name="laz_base">
    <visual>
      <geometry>
        <cylinder length="0.05" radius="0.05"/>
      </geometry>
    </visual>
    <collision>
      <geometry>
        <cylinder length="0.05" radius="0.05"/>
      </geometry>
    </collision>
    <inertial>
      <mass value="0.1"/>
      <inertia ixx="8.333333333333334e-05" ixy="0" ixz="0" iyy="8.333333333333334e-05" iyz="0" izz="0.00012500000000000003"/>
    </inertial>
  </link>
  <gazebo reference="laz_rot">
    <material>Gazebo/Blue</material>
    <mu1>0.2</mu1>
    <mu2>0.2</mu2>
    <sensor name="laz" type="ray">
      <always_on>true</always_on>
      <pose>0.04 0 12.5 1.5707963267948966 0 0</pose>
      <visualize>true</visualize>
      <update_rate>30</update_rate>
      <ray>
        <scan>
          <horizontal>
            <samples>15</samples>
            <resolution>1</resolution>
            <min_angle>-0.39269908169872414</min_angle>
            <max_angle>0.39269908169872414</max_angle>
          </horizontal>
          <vertical>
            <samples>1</samples>
            <resolution>1</resolution>
            <min_angle>-0.15</min_angle>
            <max_angle>0.15</max_angle>
          </vertical>
        </scan>
        <range>
          <min>0.05</min>
          <max>15</max>
          <resolution>0.02</resolution>
        </range>
      </ray>
    </sensor>
  </gazebo>
  <link name="laz_rot">
    <visual>
      <geometry>
        <cylinder length="50" radius="0.04"/>
      </geometry>
    </visual>
    <collision>
      <geometry>
        <cylinder length="50" radius="0.04"/>
      </geometry>
    </collision>
    <inertial>
      <mass value="0.1"/>
      <inertia ixx="20.833373333333334" ixy="0" ixz="0" iyy="20.833373333333334" iyz="0" izz="8e-05"/>
    </inertial>
  </link>
  <joint name="lazRot" type="continuous">
    <parent link="laz_base"/>
    <child link="laz_rot"/>
    <axis xyz="0 0 1"/>
    <origin xyz="0 0 0.025"/>
    <dynamics friction="0.1"/>
  </joint>
</robot>

